Aula 22.2 - Fluxo Assíncrono

Callback
Ex: 

const fs = require('fs');

fs.readFile('./arquivo.txt', (err, content) => {
  if (err) {
    console.error(`Erro ao ler o arquivo: ${err.message}`);
    return;
  }

  console.log(`Arquivo lido com sucesso. Conteúdo: ${content.toString('utf8')}`);
});



Tratando erros

Tratando erros de forma síncrona

function dividirNumeros(num1, num2) {
  if (num2 == 0) throw new Error("Não pode ser feito uma divisão por zero");

  return num1 / num2;
}

try {
  const resultado = dividirNumeros(2, 1);
  console.log(`resultado: ${resultado}`);
} catch (e) {
  console.log(e.message);
}

Tratando erros de forma assíncrona

function dividirNumeros(num1, num2) {
  const promise = new Promise((resolve, reject) => {
    if (num2 == 0) reject(new Error("Não pode ser feito uma divisão por zero"));

    const resultado = num1 / num2;
    resolve(resultado)
  });

  return promise;
}

dividirNumeros(2, 1)
  .then(result => console.log(`sucesso: ${result}`))
  .catch(err => console.log(`erro: ${err.message}`));